Workbook

Sheet Hoja1
A1: distribucion | B1: portal del sol | C1: cliente | D1: pancho | E1: haburguesa | F1: lactal blac | G1: lactal neg | H1: lomo | I1: pizza | J1: anis12 | K1: anis24 | L1: panchogrande6 | M1: alfajor glase | N1: alfajor miel | O1: alfajor maise | P1: alfajor de chocolat | Q1: pan dulce | R1: limon surtida 3kg | S1: naranja surtida 3kg | T1: coco surtida 3kg | U1: rosca glaciada | V1: Vainillas 2kg | W1: pepa 2,5kg | X1: surtida 2.5kg | Y1: surtidas 800g | Z1: surtidas 400g | AA1: miel 400g | AB1: Sandwich de miga grande | AC1: Sandwich de miga chico | AD1: pebete de jamon y queso | AE1: Sandwich miga salame gr | AF1: maisena | AG1: glaciado | AH1: miel | AJ1: conv/miel/mais | AK1: chocotorta | AL1: tiramisu | AM1: ensalda de fruta | AN1: gelatina | AP1: premium | AQ1: maisena | AR1: miel | AS1: glaciado | AT1: chocolate | AU1: combinado | AV1: alfajor frutal | AW1: miel 1kg | AX1: maisena 1kg | AY1: tartateleta cabsha
B2: 1 | C2: semana 1 (1/ 5---8/05) 2024)
B5: 1 | C5: alumine | AF5: 1 | AG5: 1
B6: 2 | C6: lisandro y balbin
B7: 3 | C7: moto
B8: 5
B9: 6
B10: 4 | C10: tejada
B11: 5 | C11: santa rosa ivana
B12: 7
B13: 8
B14: 6 | C14: riojay beltran
B16: 7 | C16: paso de los andesy cant
B17: 8 | C17: godoy 1884
B18: 9 | C18: bomba y 17 de oct
B19: 10 | C19: sguasini
B20: 11 | C20: teniete
B21: 12 | C21: negro
B22: 13 | C22: roca y sarmiento
B23: 14 | C23: roca 829
B24: 18
B25: 15 | C25: camargo
B26: 16 | C26: hugo
B27: 17 | C27: viejo almacen
B28: 22
B29: 23
B30: 18 | C30: serpa
B31: 19 | C31: villega
B32: 26
B33: 27
B34: 20 | C34: rico pan
B35: 29
B36: 21 | C36: sanguchito
B37: 22 | C37: yo
B38: 30
B39: 23 | C39: turco
B40: 24 | C40: avellaneda y rio
B42: 33
A46: =SUM(A3:A41) -> 0 | B46: total | C46: tot
D51: =SUM(D3:D50) -> 0 | E51: =SUM(E3:E50) -> 0 | F51: =SUM(F3:F50) -> 0 | G51: =SUM(G3:G50) -> 0 | H51: =SUM(H3:H50) -> 0 | I51: =SUM(I3:I50) -> 0 | J51: =SUM(J3:J50) -> 0 | K51: =SUM(K3:K50) -> 0 | ... AY51: =SUM(AY3:AY50) -> 0
...

Sheet Hoja2
A1: cliente | B1: pancho | C1: haburguesa | D1: lactal blac | E1: lactal neg | F1: lomo | G1: pizza | H1: anis12 | I1: anis24 | J1: tostadas1kg | K1: alfajor glase | L1: alfajor miel | M1: alfajor maise
A2: semana 1 3/10-.04.24 | P2: pancho | Q2: =SUM(B3:B12) -> 29 | R2: =Hoja1!S62*Q2 -> 26521.95
A3: ameguino 255 | I3: 1 | J3: 1 | P3: haburgue | Q3: =SUM(C3:C12) -> 15 | R3: =Hoja1!S61*Q3 -> 13718.25
A4: peron 23 | B4: 2 | C4: 2 | D4: 3 | E4: 3 | P4: lactal blan | Q4: =SUM(D3:D12) -> 20 | R4: =Hoja1!S64*Q4 -> 25350.06
A5: camargo | B5: 10 | C5: 5 | D5: 2 | E5: 2 | P5: lactal negr | Q5: =SUM(E3:E12) -> 5 | R5: =Hoja1!S64*Q5 -> 6337.515
A6: paso abde y canto | K6: 1 | L6: 1 | P6: lomo | Q6: =SUM(F3:F12) -> 3 | R6: =Hoja1!S66*Q6 -> 5135.136
A7: flores | I7: 1 | P7: pizza | Q7: =SUM(G3:G12) -> 5 | R7: =Hoja1!S65*Q7 -> 10569
A8: peru lemon | I8: 1 | P8: aniz12 | Q8: =SUM(H3:H12) -> 2 | R8: =Hoja1!S70*Q8 -> 3701.6
A9: palacio y corre | B9: 5 | C9: 5 | D9: 5 | F9: 3 | G9: 5 | H9: 1 | P9: anis24 | Q9: =SUM(I3:I12) -> 3 | R9: =Hoja1!S71*Q9 -> 14550.36
A10: jasinto suare | B10: 3 | C10: 3 | D10: 3 | P10: totadas1kg | Q10: =SUM(J3:J12) -> 1 | R10: =Hoja1!S76*Q10 -> 8000 | S10: costo | T10: ganacia
A11: godoy | B11: 3 | D11: 2 | H11: 1 | K11: 1 | M11: 1 | P11: alfajor glasi | Q11: =SUM(K2:K12) -> 2 | R11: =Hoja1!S72*Q11 -> 12202.4 | T11: 32000
A12: champagña | B12: 6 | D12: 5 | P12: alfajr miel | Q12: =SUM(L2:L12) -> 1 | R12: =Hoja1!S73*Q12 -> 9458.2
A16: cliente | B16: pancho | C16: haburguesa | D16: lactal blac | E16: lactal neg | F16: lomo | G16: pizza | H16: anis12 | I16: anis24 | J16: tostadas1kg | K16: alfajor glase | L16: alfajor miel | M16: alfajor maise | N16: alfajor de chocolat
A17: semana 2 10/17 -.04.24 | O17: pancho | P17: =SUM(B18:B33) -> 45 | Q17: =Y45*P17 -> 0
A18: edu peleg | B18: 5 | C18: 5 | O18: haburgue | P18: =SUM(C18:C35) -> 35 | Q18: =Y44*P18 -> 0
A19: el negro | B19: 5 | C19: 5 | D19: 2 | E19: 2 | G19: 5 | I19: 1 | J19: 1 | O19: lactal blan | P19: =SUM(D18:D35) -> 28 | Q19: =Y47*P19 -> 0
A20: godoy | B20: 3 | D20: 3 | O20: lactal negr | P20: =SUM(E18:E35) -> 6 | Q20: =Y47*P20 -> 0
A21: paso abde y canto | D21: 3 | K21: 1 | N21: 1 | O21: lomo | P21: =SUM(F18:F35) -> 0 | Q21: =Y49*P21 -> 0
A22: visetichy italia | B22: 3 | C22: 3 | D22: 3 | E22: 2 | G22: 3 | O22: pizza | P22: =SUM(G18:G35) -> 16 | Q22: =Y48*P22 -> 0
A23: peru lemon | D23: 3 | I23: 2 | O23: aniz12 | P23: =SUM(H18:H35) -> 0 | Q23: =Y53*P23 -> 0
A24: palacio y corre | B24: 6 | C24: 4 | D24: 3 | G24: 6 | O24: anis24 | P24: =SUM(I18:I35) -> 3 | Q24: =Y54*P24 -> 0
A25: jasinto suare | B25: 2 | C25: 2 | D25: 3 | O25: totadas1kg | P25: =SUM(J18:J35) -> 1 | Q25: =Y59*P25 -> 0 | R25: costo | S25: ganacia
A26: cano serp | B26: 2 | D26: 2 | E26: 2 | O26: alfajor glasi | P26: =SUM(K17:K35) -> 1 | Q26: =Y55*P26 -> 0 | S26: =Q31-R31 -> 42212
A27: champagña | B27: 12 | C27: 9 | O27: alfajr miel | P27: =SUM(L17:L35) -> 1 | Q27: =Y56*P27 -> 0
A28: 1484 Marisa | B28: 5 | C28: 5 | D28: 3 | O28: alfajor chocola | P28: =SUM(N18:N50) -> 3 | Q28: =Y58*P28 -> 0
A29: ferrarri | B29: 2 | C29: 2 | D29: 3 | G29: 2 | O29: alfajor maise | P29: =SUM(M18:M35) -> 3 | Q29: =Y57*P29 -> 0
A30: ferrari 777
A31: ameguino255 | O31: total | Q31: 135000 | R31: 92788
A32: palacio y correa
A33: camargo
A34: igana sarmi | L34: 1 | M34: 3 | N34: 1
A38: cliente | B38: pancho | C38: haburguesa | D38: lactal blac | E38: lactal neg | F38: lomo | G38: pizza | H38: anis12 | I38: anis24 | J38: tostadas1kg | K38: alfajor glase | L38: alfajor miel | M38: alfajor maise | N38: alfajor de chocolat | O38: pan rallado de 5kg | Q38: pancho | R38: =SUM(B40:B55) -> 43 | S38: =Y53*R38 -> 0
A39: semana 2 17/ 2-.04.24 | Q39: haburgue | R39: =SUM(C40:C57) -> 24 | S39: =Y52*R39 -> 0
A40: edu peleg | D40: 4 | E40: 2 | Q40: lactal blan | R40: =SUM(D40:D57) -> 16 | S40: =Y55*R40 -> 0
A41: el negro | Q41: lactal negr | R41: =SUM(E40:E57) -> 2 | S41: =Y55*R41 -> 0
A42: godoy | Q42: lomo | R42: =SUM(F40:F57) -> 0 | S42: =Y57*R42 -> 0
A43: paso abde y canto | B43: 10 | C43: 10 | Q43: pizza | R43: =SUM(G40:G57) -> 3 | S43: =Y56*R43 -> 0
A44: visetichy italia | K44: 1 | N44: 1 | Q44: aniz12 | R44: =SUM(H40:H57) -> 0 | S44: =Y61*R44 -> 0
A45: peru lemon | Q45: anis24 | R45: =SUM(I40:I57) -> 2 | S45: =Y62*R45 -> 0
A46: palacio y corre | B46: 10 | C46: 6 | Q46: totadas1kg | R46: =SUM(J40:J57) -> 0 | S46: =Y67*R46 -> 0 | T46: costo | U46: ganacia
...

Sheet Hoja3
A3: cosas hacer | B3: $$$$$$ | C3: cosas a hacer para ya
A4: 16 hablar con comedor de lavalle del negro y publicidad en radio | C4: disco solido
A5: 21 deuda con supercanal | C5: ageriadora
A6: 22 deuda con tarjeta naranja
A7: cerrar con la empresa viento andino
A8: armar cillones
A9: terminar afip,empresa y facturar
A10: buscar mesa en la casa del Carlos ser posible baúl y calesita
A12: conseguir 1000 pesos que ponga la gente
A13: conseguir que pongo 10.00$
A14: conseguir que ponga100.00$
A15: conseguir q pongan1.000.000$
A16: cambiar cortina de niños y hacer la del pasillo
A17: hacer repisas flotantes
A18: , agulos en v y y madereas
... A24: conseguir mas de 10 comedores mendoza
A28: paragolpes | B28: 150000
A30: cubiertas x4 | B30: 100000 | C30: poner camara
A31: aceite y filtro | B31: 20000
A32: comba y alineasion | B32: 30000
A33: 15-9
A35: esmalte sintetico negro
A36: video juegos maximo
A37: conseguir cuenta dolar
A38: conseguir prestamos resposable incripto
A39: en chile
A40: juego de sabana 3
A41: juego de hoyas
A42: 1 jugo de sabana para 3 1 juego de ollas 1 jarra Una nootbook Un aire portátil 3 cortina 1 mini prim buena 1 proyector 1 Microfono 1 cierra bolsa 1 impresora 1 paraguas 1 Dron
A45: ganchos para lona
A46: 2 bolsas arena
A47: cañito
... A51: llevar un tornillo

Sheet Hoja9

Sheet Hoja7

Sheet Hoja8

Sheet Hoja4

Sheet Hoja5

Sheet Hoja6
